Traceback (most recent call last):
  File "main.py", line 77, in on_message
    reply = await client.wait_for('message', timeout = 50.0, check = check1)
  File "/usr/lib/python3.8/asyncio/tasks.py", line 490, in wait_for
    raise exceptions.TimeoutError()
asyncio.exceptions.TimeoutError

During handling of the above exception, another exception occurred:

Traceback (most recent call last):
  File "/opt/virtualenvs/python3/lib/python3.8/site-packages/discord/client.py", line 312, in _run_event
    await coro(*args, **kwargs)
  File "main.py", line 78, in on_message
    except asyncio.TimeoutError:
NameError: name 'asyncio' is not defined
